Workbook

Sheet Summary
B2: Transcriber tool — screen logging quality
B3: Data: Keboola call_record (Bubble), 2026-07-13 to 2026-08-03. Testers excluded: Andreea Vrancianu, Rodrigo Gomes, Mikhail Kuzmin.
B5: THE PROBLEM
B6: The transcriber auto-logs a recruiter screen only if the call attaches to a candidate.
B7: When it does not attach, the screen is never logged and the recruiter never gets credit.
B9: HEADLINE
B10: Total calls by real recruiters | C10: 412 | E10: Source: Keboola call_record, testers removed
B11: Calls with NO candidate attached | C11: =COUNTA('Unlinked Calls'!A2:A115) -> 114 | E11: Each one is a screen that was never logged
B12: Share of calls lost | C12: =C11/C10 -> 0.27669903 | E12: Roughly 1 in 4 screens never reaches the dashboard
B14: WHY THEY FAIL
B15: Failure mode | C15: Calls | D15: % of lost | E15: What it means
B16: Completed but never linked | C16: =COUNTIF('Unlinked Calls'!$A$2:$A$115,$B16) -> 55 | D16: =IFERROR(C16/$C$11,0) -> 0.48245614 | E16: Transcript and summary both fine. Simply never attached. A silent failure with no error logged.
B17: No audio captured | C17: =COUNTIF('Unlinked Calls'!$A$2:$A$115,$B17) -> 35 | D17: =IFERROR(C17/$C$11,0) -> 0.30701754 | E17: Transcript failed or timed out. Two errors dominate: empty transcription, and no spoken audio.
B18: Stuck processing | C18: =COUNTIF('Unlinked Calls'!$A$2:$A$115,$B18) -> 13 | D18: =IFERROR(C18/$C$11,0) -> 0.11403509 | E18: Still sitting in "running". Never reached a terminal state, so it never linked.
B19: Not a screen | C19: =COUNTIF('Unlinked Calls'!$A$2:$A$115,$B19) -> 11 | D19: =IFERROR(C19/$C$11,0) -> 0.096491228 | E19: Internal 1:1s, syncs, intakes and offer chats the tool recorded anyway. Correctly unlinked.
B20: TOTAL | C20: =SUM(C16:C19) -> 114 | D20: =SUM(D16:D19) -> 1
B22: WHAT THIS TELLS US
B23: • | C23: It is NOT a version problem. Every extension version sits near 25-30% unlinked, so upgrading will not fix it.
B24: • | C24: It fails silently. 97 of the 114 lost calls carry no error text at all, so nobody notices.
B25: • | C25: It is not inherent to the tool. Marina Nikolic: 68 calls, zero lost. Lejla Silva: 31 calls, one lost.
B26: • | C26: Kristina Colovic is the worst hit: 22 of 34 calls lost. She was also losing 23 screens to the separate attribution bug fixed today.
B27: • | C27: Titles look decisive. Calls titled with a raw Google Meet code (e.g. "qbj-pvas-qeo") give the matcher no name to work with.
B28: • | C28: Blank participant name is the other strong signal. Where PARTICIPANT is empty, linking almost always fails.
B29: • | C29: Linkage and transcription are two different bugs. Lejla links almost perfectly but loses 9 of 31 transcripts.
B31: SUGGESTED NEXT STEPS FOR MIKHAIL
B32: → | C32: Take the 63 "Completed but never linked" rows and work out why the candidate match failed when everything else worked.
B33: → | C33: Add an explicit failure state. A call that finishes without attaching to a candidate should raise an error, not pass silently.
B34: → | C34: Check whether the matcher relies on the meeting title. If so, Meet-code titles will always fail and need a fallback.
B35: → | C35: Compare Marina Nikolic and Lejla Silva against Kristina Colovic. Same tool, opposite outcomes, so the difference is findable.
B36: → | C36: Handle the empty-transcription and no-spoken-audio errors separately. That is an audio capture bug, not a linking bug.
B37: → | C37: Filter internal meetings out of screening mode so 1:1s and syncs stop entering the pipeline at all.
B39: CAVEAT ON VLADIMIR
B40: Vladimir has only 19 call records in a period where he reports about 46 screens. Even if every one had linked, it would not close his gap. He is mostly screening without the tool, which is a separate issue from this one.

Sheet Unlinked Calls
A1: CATEGORY | B1: WHAT_IT_MEANS | C1: RECRUITER | D1: DATE | E1: ISO_WEEK | F1: PARTICIPANT | G1: MEET_TITLE | H1: JOB_NAME | I1: JOB_LINKED | J1: TITLE_IS_MEET_CODE | K1: PARTICIPANT_BLANK | L1: STATUS | M1: TRANSCRIPT | N1: SUMMARY | O1: CALL_MODE | P1: EXT_VERSION | Q1: ERROR_TEXT | R1: CALL_ID
A2: Completed but never linked | B2: SILENT FAILURE - transcript and summary fine, no candidate attached | C2: Aleksandra Vistac | D2: 2026-07-28 | E2: 31 | F2: Robert Kübler | G2: Initial Call with Enam (Robert Kübler) | H2: Machine Learning Engineer - Enam | I2: yes | L2: finished | M2: generated | N2: generated | O2: screening | P2: 5.0.8 | R2: 1785230290618
A3: Completed but never linked | B3: SILENT FAILURE - transcript and summary fine, no candidate attached | C3: Aleksandra Vistac | D3: 2026-07-28 | E3: 31 | F3: sergio wantumba | G3: Initial Call with Enam (sergio wantumba) | H3: Fullstack Engineer - Enam | I3: yes | L3: finished | M3: generated | N3: generated | O3: screening | P3: 5.0.8 | R3: 1785227667316
A4: Completed but never linked | B4: SILENT FAILURE - transcript and summary fine, no candidate attached | C4: Aleksandra Vistac | D4: 2026-07-28 | E4: 31 | F4: Moha Najafi | G4: Initial Call with Enam (Moha Najafi) | H4: Security & Compliance Engineer - Enam | I4: yes | L4: finished | M4: generated | N4: generated | O4: screening | P4: 5.0.8 | R4: 1785222227323
A5: Completed but never linked | B5: SILENT FAILURE - transcript and summary fine, no candidate attached | C5: Aleksandra Vistac | D5: 2026-07-29 | E5: 31 | F5: Szymon Polom | G5: Initial Call with Enam (Szymon Polom) | H5: Fullstack Engineer - Enam | I5: yes | L5: finished | M5: generated | N5: generated | O5: screening | P5: 5.0.8 | R5: 1785324794268
A6: Completed but never linked | B6: SILENT FAILURE - transcript and summary fine, no candidate attached | C6: Aleksandra Vistac | D6: 2026-07-29 | E6: 31 | F6: Srinidhi Patil | G6: Initial Call with Enam (Srinidhi Patil) | H6: Machine Learning Engineer - Enam | I6: yes | L6: finished | M6: generated | N6: generated | O6: screening | P6: 5.0.8 | R6: 1785319413348
A7: Completed but never linked | B7: SILENT FAILURE - transcript and summary fine, no candidate attached | C7: Aleksandra Vistac | D7: 2026-07-30 | E7: 31 | F7: Tsovak Sahakyan | G7: Initial Call with Enam (Tsovak Sahakyan) | H7: Fullstack Engineer - Enam | I7: yes | L7: finished | M7: generated | N7: generated | O7: screening | P7: 5.0.8 | R7: 1785411182750
A8: Completed but never linked | B8: SILENT FAILURE - transcript and summary fine, no candidate attached | C8: Aleksandra Vistac | D8: 2026-07-30 | E8: 31 | F8: Siddarth Pawar | G8: Initial Call with Enam (Siddarth Pawar - Fullstack Interview - Enam) | H8: Fullstack Engineer - Enam | I8: yes | L8: finished | M8: generated | N8: generated | O8: screening | P8: 5.0.8 | R8: 1785405904694
A9: Completed but never linked | B9: SILENT FAILURE - transcript and summary fine, no candidate attached | C9: Aleksandra Vistac | D9: 2026-07-30 | E9: 31 | F9: Onur Kuru | G9: Initial Call with Enam (Onur Kuru) | H9: Machine Learning Engineer - Enam | I9: yes | L9: finished | M9: generated | N9: generated | O9: screening | P9: 5.0.8 | R9: 1785408549916
A10: Completed but never linked | B10: SILENT FAILURE - transcript and summary fine, no candidate attached | C10: Aleksandra Vistac | D10: 2026-07-30 | E10: 31 | F10: Kamila Kinayat | G10: Initial Call with Enam (Kamila Kinayat) | H10: Machine Learning Engineer - Enam | I10: yes | L10: finished | M10: generated | N10: generated | O10: screening | P10: 5.0.8 | R10: 1785397656254
A11: Completed but never linked | B11: SILENT FAILURE - transcript and summary fine, no candidate attached | C11: Aleksandra Vistac | D11: 2026-07-31 | E11: 31 | F11: Artur Thiessen | G11: Initial Call with Enam (Artur Thiessen - Fullstack Interview Enam) | H11: Fullstack Engineer - Enam | I11: yes | L11: finished | M11: generated | N11: generated | O11: screening | P11: 5.0.8 | R11: 1785494978125
A12: Completed but never linked | B12: SILENT FAILURE - transcript and summary fine, no candidate attached | C12: Aleksandra Vistac | D12: 2026-07-31 | E12: 31 | F12: Elie Kawerk | G12: Initial Call with Enam (Elie Kawerk) | H12: Machine Learning Engineer - Enam | I12: yes | L12: finished | M12: generated | N12: generated | O12: screening | P12: 5.0.8 | R12: 1785492264648
A13: Completed but never linked | B13: SILENT FAILURE - transcript and summary fine, no candidate attached | C13: Aleksandra Vistac | D13: 2026-08-03 | E13: 32 | F13: Sevet Gokay | G13: Initial Call with Enam (Sevet Gokay - FS Enam 1st Interview) | H13: Fullstack Engineer - Enam | I13: yes | L13: finished | M13: generated | N13: generated | O13: screening | P13: 5.0.8 | R13: 1785746140312
... A15: Completed but never linked | B15: SILENT FAILURE - transcript and summary fine, no candidate attached | C15: Aleksandra Vistac | D15: 2026-08-03 | E15: 32 | F15: Henry Ofozor | G15: Initial Call with Enam (Henry Ofozor) | H15: Security & Compliance Engineer - Enam | I15: yes | L15: finished | M15: generated | N15: generated | O15: screening | P15: 5.0.9 | R15: 1785759449028
A16: Completed but never linked | B16: SILENT FAILURE - transcript and summary fine, no candidate attached | C16: Chené Elliot | D16: 2026-07-27 | E16: 31 | F16: qbj-pvas-qeo | G16: qbj-pvas-qeo | H16: Product Designer Glovo - Glovo | I16: yes | J16: YES | L16: finished | M16: generated | N16: generated | O16: screening | P16: 5.0.8 | R16: 1785144652639
A17: Completed but never linked | B17: SILENT FAILURE - transcript and summary fine, no candidate attached | C17: Chené Elliot | D17: 2026-07-29 | E17: 31 | F17: bwh-ajra-vtm | G17: bwh-ajra-vtm | H17: Product Designer Glovo - Glovo | I17: yes | J17: YES | L17: finished | M17: generated | N17: generated | O17: screening | P17: 5.0.8 | R17: 1785331897019
A18: Completed but never linked | B18: SILENT FAILURE - transcript and summary fine, no candidate attached | C18: Chené Elliot | D18: 2026-07-29 | E18: 31 | F18: omf-naob-vvw | G18: omf-naob-vvw | H18: Product Designer Glovo - Glovo | I18: yes | J18: YES | L18: finished | M18: generated | N18: generated | O18: screening | P18: 5.0.8 | R18: 1785318375856
A19: Completed but never linked | B19: SILENT FAILURE - transcript and summary fine, no candidate attached | C19: Dušan Špica | D19: 2026-07-16 | E19: 29 | F19: Temi Olugbake | G19: Temi Olugbake: 30 Minute Talent Interview | H19: Senior Software Engineer (UK) - Fullstack (Ecosystem/Shop) - Eucalyptus | I19: yes | L19: finished | M19: generated | N19: generated | O19: screening | R19: 1784198441152
A20: Completed but never linked | B20: SILENT FAILURE - transcript and summary fine, no candidate attached | C20: Dušan Špica | D20: 2026-07-16 | E20: 29 | F20: AJ Lawal | G20: AJ Lawal: 30 Minute Talent Interview | H20: Analytics Engineer - Eucalyptus | I20: yes | L20: finished | M20: generated | N20: generated | O20: screening | R20: 1784199697556
A21: Completed but never linked | B21: SILENT FAILURE - transcript and summary fine, no candidate attached | C21: Dušan Špica | D21: 2026-07-17 | E21: 29 | F21: Dusan | G21: Talent Interview - Dusan & Vijayalaxmi Vastrad | H21: Senior Software Engineer (UK) - Fullstack (Ecosystem/Shop) - Eucalyptus | I21: yes | L21: finished | M21: generated | N21: generated | O21: screening | P21: 5.0.6 | R21: 1784296841772
A22: Completed but never linked | B22: SILENT FAILURE - transcript and summary fine, no candidate attached | C22: Filip Nogowski | D22: 2026-07-21 | E22: 30 | F22: Kelechukwu Nwosu | G22: Kelechukwu Nwosu and Filip Nogowski | I22: NO | L22: finished | M22: generated | N22: generated | O22: screening | P22: 5.0.7 | R22: 1784630001611
A23: Completed but never linked | B23: SILENT FAILURE - transcript and summary fine, no candidate attached | C23: Fuad Safarov | D23: 2026-07-24 | E23: 30 | F23: Ritik Khandelwal | G23: Recruiter Screen, Account Executive - Ritik Khandelwal | H23: Account Executive - India - Aiven | I23: yes | L23: finished | M23: generated | N23: generated | O23: screening | P23: 5.0.8 | R23: 1784898023631
A24: Completed but never linked | B24: SILENT FAILURE - transcript and summary fine, no candidate attached | C24: Iryna Dyda | D24: 2026-07-16 | E24: 29 | F24: Luka Burian | G24: Meet – Luka Burian and Iryna Dyda | H24: Junior Backend Developer - France - AVIV | I24: yes | L24: finished | M24: generated | N24: generated | O24: screening | R24: 1784205066564
A25: Completed but never linked | B25: SILENT FAILURE - transcript and summary fine, no candidate attached | C25: Iryna Dyda | D25: 2026-07-30 | E25: 31 | F25: Milan Rakoš | G25: Meet – Milan Rakoš and Iryna Dyda | H25: Frontend Engineer - Croatia - AVIV | I25: yes | L25: finished | M25: generated | N25: generated | O25: screening | P25: 5.0.8 | R25: 1785405703984
A26: Completed but never linked | B26: SILENT FAILURE - transcript and summary fine, no candidate attached | C26: Iryna Dyda | D26: 2026-07-30 | E26: 31 | F26: Mario Sparica | G26: Meet – Mario Sparica: 30 Minute Meeting | H26: Backend Engineer - Croatia - AVIV | I26: yes | L26: finished | M26: generated | N26: generated | O26: screening | P26: 5.0.8 | R26: 1785411102178
A27: Completed but never linked | B27: SILENT FAILURE - transcript and summary fine, no candidate attached | C27: Jelena Lacmanovic | D27: 2026-07-21 | E27: 30 | F27: Jure Todoric | G27: Meet – Jure Todoric: 30 Minute Meeting | H27: Senior Salesforce Developer (Contract) - AVIV | I27: yes | L27: finished | M27: generated | N27: generated | O27: screening | P27: 5.0.7 | R27: 1784633497227
A28: Completed but never linked | B28: SILENT FAILURE - transcript and summary fine, no candidate attached | C28: Jelena Lacmanovic | D28: 2026-07-28 | E28: 31 | F28: Branimir Svabic | G28: Meet – Branimir Svabic: 30 Minute Meeting | H28: Backend Engineer - Croatia - AVIV | I28: yes | L28: finished | M28: generated | N28: generated | O28: screening | P28: 5.0.8 | R28: 1785238254304
A29: Completed but never linked | B29: SILENT FAILURE - transcript and summary fine, no candidate attached | C29: Kristina Colovic | D29: 2026-07-21 | E29: 30 | F29: Oleg Yasnev | G29: Meet – Oleg Yasnev and Kristina Colovic | H29: Engineering Manager, Platform - Berlin - AVIV | I29: yes | L29: finished | M29: generated | N29: generated | O29: screening | P29: 5.0.7 | R29: 1784633391795
A30: Completed but never linked | B30: SILENT FAILURE - transcript and summary fine, no candidate attached | C30: Kristina Colovic | D30: 2026-07-24 | E30: 30 | F30: Julian Gog | G30: Meet – Julian Gog and Wladyslaw Gadomski | H30: Engineering Manager, Platform - Berlin - AVIV | I30: yes | L30: finished | M30: generated | N30: generated | O30: screening | P30: 5.0.8 | R30: 1784887176457
A31: Completed but never linked | B31: SILENT FAILURE - transcript and summary fine, no candidate attached | C31: Kristina Colovic | D31: 2026-07-24 | E31: 30 | F31: Thomas berrod | G31: Meet – Thomas berrod and Kristina Colovic | H31: Engineering Manager France, Kristina - AVIV | I31: yes | L31: finished | M31: generated | N31: generated | O31: screening | P31: 5.0.8 | R31: 1784885356197
A32: Completed but never linked | B32: SILENT FAILURE - transcript and summary fine, no candidate attached | C32: Kristina Colovic | D32: 2026-07-29 | E32: 31 | F32: Lionel Martin | G32: Meet – Lionel Martin and Kristina Colovic | H32: Engineering Manager France, Kristina - AVIV | I32: yes | L32: finished | M32: generated | N32: generated | O32: screening | P32: 5.0.8 | R32: 1785331853573
A33: Completed but never linked | B33: SILENT FAILURE - transcript and summary fine, no candidate attached | C33: Kristina Colovic | D33: 2026-07-29 | E33: 31 | F33: Manikandan Kandasamy | G33: Meet – Manikandan Kandasamy and Kristina Colovic | H33: Staff Backend Engineer Trust & Safety - Kristina - Berlin - AVIV | I33: yes | L33: finished | M33: generated | N33: generated | O33: screening | P33: 5.0.8 | R33: 1785321069123
A34: Completed but never linked | B34: SILENT FAILURE - transcript and summary fine, no candidate attached | C34: Kristina Colovic | D34: 2026-07-29 | E34: 31 | F34: Manikandan Kandasamy | G34: Meet – Manikandan Kandasamy and Kristina Colovic | H34: Staff Backend Engineer Trust & Safety - Kristina - Berlin - AVIV | I34: yes | L34: finished | M34: generated | N34: generated | O34: screening | P34: 5.0.8 | R34: 1785320998173
A35: Completed but never linked | B35: SILENT FAILURE - transcript and summary fine, no candidate attached | C35: Kristina Colovic | D35: 2026-07-31 | E35: 31 | F35: Evgenii Bazhanov | G35: Meet – Evgenii Bazhanov and Kristina Colovic | H35: QA Engineer, Automation - AVIV | I35: yes | L35: finished | M35: generated | N35: generated | O35: screening | P35: 5.0.8 | R35: 1785493805563
A36: Completed but never linked | B36: SILENT FAILURE - transcript and summary fine, no candidate attached | C36: Kristina Colovic | D36: 2026-07-31 | E36: 31 | F36: Manikandan Karunanidhi | G36: Meet – Manikandan Karunanidhi and Kristina Colovic | H36: QA Engineer, Automation - AVIV | I36: yes | L36: finished | M36: generated | N36: generated | O36: screening | P36: 5.0.8 | R36: 1785499216552
... A38: Completed but never linked | B38: SILENT FAILURE - transcript and summary fine, no candidate attached | C38: Kristina Colovic | D38: 2026-07-31 | E38: 31 | F38: M Aaqib Habib | G38: Meet – M Aaqib Habib and Kristina Colovic | H38: QA Engineer, Automation - AVIV | I38: yes | L38: finished | M38: generated | N38: generated | O38: screening | P38: 5.0.8 | R38: 1785502904853
A39: Completed but never linked | B39: SILENT FAILURE - transcript and summary fine, no candidate attached | C39: Kristina Colovic | D39: 2026-07-31 | E39: 31 | F39: M Aaqib Habib | G39: Meet – M Aaqib Habib and Kristina Colovic | I39: NO | L39: finished | M39: generated | N39: generated | O39: screening | P39: 5.0.8 | R39: 1785503559209
A40: Completed but never linked | B40: SILENT FAILURE - transcript and summary fine, no candidate attached | C40: Kristina Colovic | D40: 2026-08-03 | E40: 32 | F40: Saqib Ahmed | G40: Meet – Saqib Ahmed and Kristina Colovic | H40: QA Engineer, Automation - AVIV | I40: yes | L40: finished | M40: generated | N40: generated | O40: screening | P40: 5.0.8 | R40: 1785745853502
A41: Completed but never linked | B41: SILENT FAILURE - transcript and summary fine, no candidate attached | C41: Lejla Silva | D41: 2026-07-22 | E41: 30 | F41: Mohssine ARDI | G41: Meet: Mohssine ARDI and Lejla Dizdarevic | I41: NO | L41: finished | M41: generated | N41: generated | O41: screening | P41: 5.0.8 | R41: 1784713171030
A42: Completed but never linked | B42: SILENT FAILURE - transcript and summary fine, no candidate attached | C42: Lisa Gargulinska | D42: 2026-07-27 | E42: 31 | F42: Fabian | G42: Wolt and Fabian | Video Interview | H42: Team Lead Sales, Region North - Wolt | I42: yes | L42: finished | M42: generated | N42: generated | O42: screening | P42: 5.0.8 | R42: 1785142660872
...

Sheet By Recruiter
A1: Transcriber linkage by recruiter
A2: Testers excluded (Andreea Vrancianu, Rodrigo Gomes, Mikhail Kuzmin) per Blake, 2026-08-03.
A4: Recruiter | B4: Total calls | C4: Unlinked | D4: % unlinked | E4: Completed but never linked | F4: No audio captured | G4: Stuck processing | H4: Not a screen
A5: Marina Nikolic | B5: 68 | C5: =COUNTIF('Unlinked Calls'!$C$2:$C$115,$A5) -> 0 | D5: =IFERROR(C5/B5,0) -> 0 | E5: =COUNTIFS('Unlinked Calls'!$C$2:$C$115,$A5,'Unlinked Calls'!$A$2:$A$115,"Completed but never linked") -> 0 | F5: =COUNTIFS('Unlinked Calls'!$C$2:$C$115,$A5,'Unlinked Calls'!$A$2:$A$115,"No audio captured") -> 0 | G5: =COUNTIFS('Unlinked Calls'!$C$2:$C$115,$A5,'Unlinked Calls'!$A$2:$A$115,"Stuck processing") -> 0 | H5: =COUNTIFS('Unlinked Calls'!$C$2:$C$115,$A5,'Unlinked Calls'!$A$2:$A$115,"Not a screen") -> 0
A6: Simon Siew | B6: 40 | C6: =COUNTIF('Unlinked Calls'!$C$2:$C$115,$A6) -> 5 | D6: =IFERROR(C6/B6,0) -> 0.125 | E6: =COUNTIFS('Unlinked Calls'!$C$2:$C$115,$A6,'Unlinked Calls'!$A$2:$A$115,"Completed but never linked") -> 2 | F6: =COUNTIFS('Unlinked Calls'!$C$2:$C$115,$A6,'Unlinked Calls'!$A$2:$A$115,"No audio captured") -> 3 | G6: =COUNTIFS('Unlinked Calls'!$C$2:$C$115,$A6,'Unlinked Calls'!$A$2:$A$115,"Stuck processing") -> 0 | H6: =COUNTIFS('Unlinked Calls'!$C$2:$C$115,$A6,'Unlinked Calls'!$A$2:$A$115,"Not a screen") -> 0
A7: Aleksandra Vistac | B7: 38 | C7: =COUNTIF('Unlinked Calls'!$C$2:$C$115,$A7) -> 17 | D7: =IFERROR(C7/B7,0) -> 0.44736842 | E7: =COUNTIFS('Unlinked Calls'!$C$2:$C$115,$A7,'Unlinked Calls'!$A$2:$A$115,"Completed but never linked") -> 14 | F7: =COUNTIFS('Unlinked Calls'!$C$2:$C$115,$A7,'Unlinked Calls'!$A$2:$A$115,"No audio captured") -> 1 | G7: =COUNTIFS('Unlinked Calls'!$C$2:$C$115,$A7,'Unlinked Calls'!$A$2:$A$115,"Stuck processing") -> 1 | H7: =COUNTIFS('Unlinked Calls'!$C$2:$C$115,$A7,'Unlinked Calls'!$A$2:$A$115,"Not a screen") -> 1
A8: Kristina Colovic | B8: 34 | C8: =COUNTIF('Unlinked Calls'!$C$2:$C$115,$A8) -> 22 | D8: =IFERROR(C8/B8,0) -> 0.64705882 | E8: =COUNTIFS('Unlinked Calls'!$C$2:$C$115,$A8,'Unlinked Calls'!$A$2:$A$115,"Completed but never linked") -> 12 | F8: =COUNTIFS('Unlinked Calls'!$C$2:$C$115,$A8,'Unlinked Calls'!$A$2:$A$115,"No audio captured") -> 5 | G8: =COUNTIFS('Unlinked Calls'!$C$2:$C$115,$A8,'Unlinked Calls'!$A$2:$A$115,"Stuck processing") -> 5 | H8: =COUNTIFS('Unlinked Calls'!$C$2:$C$115,$A8,'Unlinked Calls'!$A$2:$A$115,"Not a screen") -> 0
A9: Lejla Silva | B9: 31 | C9: =COUNTIF('Unlinked Calls'!$C$2:$C$115,$A9) -> 1 | D9: =IFERROR(C9/B9,0) -> 0.032258065 | E9: =COUNTIFS('Unlinked Calls'!$C$2:$C$115,$A9,'Unlinked Calls'!$A$2:$A$115,"Completed but never linked") -> 1 | F9: =COUNTIFS('Unlinked Calls'!$C$2:$C$115,$A9,'Unlinked Calls'!$A$2:$A$115,"No audio captured") -> 0 | G9: =COUNTIFS('Unlinked Calls'!$C$2:$C$115,$A9,'Unlinked Calls'!$A$2:$A$115,"Stuck processing") -> 0 | H9: =COUNTIFS('Unlinked Calls'!$C$2:$C$115,$A9,'Unlinked Calls'!$A$2:$A$115,"Not a screen") -> 0
A10: Dušan Špica | B10: 28 | C10: =COUNTIF('Unlinked Calls'!$C$2:$C$115,$A10) -> 7 | D10: =IFERROR(C10/B10,0) -> 0.25 | E10: =COUNTIFS('Unlinked Calls'!$C$2:$C$115,$A10,'Unlinked Calls'!$A$2:$A$115,"Completed but never linked") -> 3 | F10: =COUNTIFS('Unlinked Calls'!$C$2:$C$115,$A10,'Unlinked Calls'!$A$2:$A$115,"No audio captured") -> 0 | G10: =COUNTIFS('Unlinked Calls'!$C$2:$C$115,$A10,'Unlinked Calls'!$A$2:$A$115,"Stuck processing") -> 0 | H10: =COUNTIFS('Unlinked Calls'!$C$2:$C$115,$A10,'Unlinked Calls'!$A$2:$A$115,"Not a screen") -> 4
A11: Samantha Nel | B11: 28 | C11: =COUNTIF('Unlinked Calls'!$C$2:$C$115,$A11) -> 5 | D11: =IFERROR(C11/B11,0) -> 0.17857143 | E11: =COUNTIFS('Unlinked Calls'!$C$2:$C$115,$A11,'Unlinked Calls'!$A$2:$A$115,"Completed but never linked") -> 2 | F11: =COUNTIFS('Unlinked Calls'!$C$2:$C$115,$A11,'Unlinked Calls'!$A$2:$A$115,"No audio captured") -> 1 | G11: =COUNTIFS('Unlinked Calls'!$C$2:$C$115,$A11,'Unlinked Calls'!$A$2:$A$115,"Stuck processing") -> 1 | H11: =COUNTIFS('Unlinked Calls'!$C$2:$C$115,$A11,'Unlinked Calls'!$A$2:$A$115,"Not a screen") -> 1
A12: Jelena Lacmanovic | B12: 25 | C12: =COUNTIF('Unlinked Calls'!$C$2:$C$115,$A12) -> 9 | D12: =IFERROR(C12/B12,0) -> 0.36 | E12: =COUNTIFS('Unlinked Calls'!$C$2:$C$115,$A12,'Unlinked Calls'!$A$2:$A$115,"Completed but never linked") -> 2 | F12: =COUNTIFS('Unlinked Calls'!$C$2:$C$115,$A12,'Unlinked Calls'!$A$2:$A$115,"No audio captured") -> 7 | G12: =COUNTIFS('Unlinked Calls'!$C$2:$C$115,$A12,'Unlinked Calls'!$A$2:$A$115,"Stuck processing") -> 0 | H12: =COUNTIFS('Unlinked Calls'!$C$2:$C$115,$A12,'Unlinked Calls'!$A$2:$A$115,"Not a screen") -> 0
A13: Fuad Safarov | B13: 20 | C13: =COUNTIF('Unlinked Calls'!$C$2:$C$115,$A13) -> 5 | D13: =IFERROR(C13/B13,0) -> 0.25 | E13: =COUNTIFS('Unlinked Calls'!$C$2:$C$115,$A13,'Unlinked Calls'!$A$2:$A$115,"Completed but never linked") -> 1 | F13: =COUNTIFS('Unlinked Calls'!$C$2:$C$115,$A13,'Unlinked Calls'!$A$2:$A$115,"No audio captured") -> 4 | G13: =COUNTIFS('Unlinked Calls'!$C$2:$C$115,$A13,'Unlinked Calls'!$A$2:$A$115,"Stuck processing") -> 0 | H13: =COUNTIFS('Unlinked Calls'!$C$2:$C$115,$A13,'Unlinked Calls'!$A$2:$A$115,"Not a screen") -> 0
A14: Vladimir Stankovic | B14: 19 | C14: =COUNTIF('Unlinked Calls'!$C$2:$C$115,$A14) -> 7 | D14: =IFERROR(C14/B14,0) -> 0.36842105 | E14: =COUNTIFS('Unlinked Calls'!$C$2:$C$115,$A14,'Unlinked Calls'!$A$2:$A$115,"Completed but never linked") -> 4 | F14: =COUNTIFS('Unlinked Calls'!$C$2:$C$115,$A14,'Unlinked Calls'!$A$2:$A$115,"No audio captured") -> 1 | G14: =COUNTIFS('Unlinked Calls'!$C$2:$C$115,$A14,'Unlinked Calls'!$A$2:$A$115,"Stuck processing") -> 1 | H14: =COUNTIFS('Unlinked Calls'!$C$2:$C$115,$A14,'Unlinked Calls'!$A$2:$A$115,"Not a screen") -> 1
A15: Chené Elliot | B15: 19 | C15: =COUNTIF('Unlinked Calls'!$C$2:$C$115,$A15) -> 5 | D15: =IFERROR(C15/B15,0) -> 0.26315789 | E15: =COUNTIFS('Unlinked Calls'!$C$2:$C$115,$A15,'Unlinked Calls'!$A$2:$A$115,"Completed but never linked") -> 3 | F15: =COUNTIFS('Unlinked Calls'!$C$2:$C$115,$A15,'Unlinked Calls'!$A$2:$A$115,"No audio captured") -> 2 | G15: =COUNTIFS('Unlinked Calls'!$C$2:$C$115,$A15,'Unlinked Calls'!$A$2:$A$115,"Stuck processing") -> 0 | H15: =COUNTIFS('Unlinked Calls'!$C$2:$C$115,$A15,'Unlinked Calls'!$A$2:$A$115,"Not a screen") -> 0
A16: Jan Dokulil | B16: 17 | C16: =COUNTIF('Unlinked Calls'!$C$2:$C$115,$A16) -> 2 | D16: =IFERROR(C16/B16,0) -> 0.11764706 | E16: =COUNTIFS('Unlinked Calls'!$C$2:$C$115,$A16,'Unlinked Calls'!$A$2:$A$115,"Completed but never linked") -> 0 | F16: =COUNTIFS('Unlinked Calls'!$C$2:$C$115,$A16,'Unlinked Calls'!$A$2:$A$115,"No audio captured") -> 1 | G16: =COUNTIFS('Unlinked Calls'!$C$2:$C$115,$A16,'Unlinked Calls'!$A$2:$A$115,"Stuck processing") -> 0 | H16: =COUNTIFS('Unlinked Calls'!$C$2:$C$115,$A16,'Unlinked Calls'!$A$2:$A$115,"Not a screen") -> 1
... A26: Unknown user | B26: 1 | C26: =COUNTIF('Unlinked Calls'!$C$2:$C$115,$A26) -> 1 | D26: =IFERROR(C26/B26,0) -> 1 | E26: =COUNTIFS('Unlinked Calls'!$C$2:$C$115,$A26,'Unlinked Calls'!$A$2:$A$115,"Completed but never linked") -> 0 | F26: =COUNTIFS('Unlinked Calls'!$C$2:$C$115,$A26,'Unlinked Calls'!$A$2:$A$115,"No audio captured") -> 1 | G26: =COUNTIFS('Unlinked Calls'!$C$2:$C$115,$A26,'Unlinked Calls'!$A$2:$A$115,"Stuck processing") -> 0 | H26: =COUNTIFS('Unlinked Calls'!$C$2:$C$115,$A26,'Unlinked Calls'!$A$2:$A$115,"Not a screen") -> 0
A27: TOTAL | B27: =SUM(B5:B26) -> 412 | C27: =SUM(C5:C26) -> 114 | D27: =IFERROR(C27/B27,0) -> 0.27669903 | E27: =SUM(E5:E26) -> 55 | F27: =SUM(F5:F26) -> 35 | G27: =SUM(G5:G26) -> 13 | H27: =SUM(H5:H26) -> 11
A29: Blue = source data pulled from Keboola call_record. Black = calculated from the Unlinked Calls tab.
